Traceback (most recent call last):
  File "/home/codespace/.cache/pypoetry/virtualenvs/articlepublishingtesting-2ECuybf9-py3.12/lib/python3.12/site-packages/jupyter_cache/executors/utils.py", line 58, in single_nb_execution
    executenb(
  File "/home/codespace/.cache/pypoetry/virtualenvs/articlepublishingtesting-2ECuybf9-py3.12/lib/python3.12/site-packages/nbclient/client.py", line 1319, in execute
    return NotebookClient(nb=nb, resources=resources, km=km, **kwargs).execute()
           ^^^^^^^^^^^^^^^^^^^^^^^^^^^^^^^^^^^^^^^^^^^^^^^^^^^^^^^^^^^^^^^^^^^^^
  File "/home/codespace/.cache/pypoetry/virtualenvs/articlepublishingtesting-2ECuybf9-py3.12/lib/python3.12/site-packages/jupyter_core/utils/__init__.py", line 165, in wrapped
    return loop.run_until_complete(inner)
           ^^^^^^^^^^^^^^^^^^^^^^^^^^^^^^
  File "/usr/local/python/3.12.1/lib/python3.12/asyncio/base_events.py", line 684, in run_until_complete
    return future.result()
           ^^^^^^^^^^^^^^^
  File "/home/codespace/.cache/pypoetry/virtualenvs/articlepublishingtesting-2ECuybf9-py3.12/lib/python3.12/site-packages/nbclient/client.py", line 709, in async_execute
    await self.async_execute_cell(
  File "/home/codespace/.cache/pypoetry/virtualenvs/articlepublishingtesting-2ECuybf9-py3.12/lib/python3.12/site-packages/nbclient/client.py", line 1062, in async_execute_cell
    await self._check_raise_for_error(cell, cell_index, exec_reply)
  File "/home/codespace/.cache/pypoetry/virtualenvs/articlepublishingtesting-2ECuybf9-py3.12/lib/python3.12/site-packages/nbclient/client.py", line 918, in _check_raise_for_error
    raise CellExecutionError.from_cell_and_msg(cell, exec_reply_content)
nbclient.exceptions.CellExecutionError: An error occurred while executing the following cell:
------------------
# Download the Facebook metrics dataset
import kagglehub
facebook_metrics_path = kagglehub.dataset_download('masoodanzar/facebook-metrics')

# Get input data file pathsin the
paths_input_files = []
import os
for dirname, _, filenames in os.walk('/kaggle/input'):
    for filename in filenames:
# check file paths
        paths_input_files.append(os.path.join(dirname, filename))

print(paths_input_files)

# Import libraries for Analysis
import pandas as pd # data processing, CSV file I/O (e.g. pd.read_csv)
import numpy as np # linear algebra
import matplotlib.pyplot as plt # data visualisations
import seaborn as sns # more data visualisations

display("Setup Completed")  
------------------


[0;31m---------------------------------------------------------------------------[0m
[0;31mModuleNotFoundError[0m                       Traceback (most recent call last)
Cell [0;32mIn[1], line 2[0m
[1;32m      1[0m [38;5;66;03m# Download the Facebook metrics dataset[39;00m
[0;32m----> 2[0m [38;5;28;01mimport[39;00m[38;5;250m [39m[38;5;21;01mkagglehub[39;00m
[1;32m      3[0m facebook_metrics_path [38;5;241m=[39m kagglehub[38;5;241m.[39mdataset_download([38;5;124m'[39m[38;5;124mmasoodanzar/facebook-metrics[39m[38;5;124m'[39m)
[1;32m      5[0m [38;5;66;03m# Get input data file pathsin the[39;00m

[0;31mModuleNotFoundError[0m: No module named 'kagglehub'

